<mujoco model="Body">
    <compiler angle="radian" />
    <size njmax="500" nconmax="100" />
    <asset>
        <mesh name="underwater_insect_robot_base_coll_1"    file="underwater_insect_robot/underwater_insect_robot_base_coll_1.stl" />
        <mesh name="underwater_insect_FR_L1_coll_1"         file="underwater_insect_robot/underwater_insect_FR_L1_coll_1.stl" />
        <mesh name="underwater_insect_FR_L2_coll_1"         file="underwater_insect_robot/underwater_insect_FR_L2_coll_1.stl" />
        <mesh name="underwater_insect_FR_L3_coll_1"         file="underwater_insect_robot/underwater_insect_FR_L3_coll_1.stl" />
        <mesh name="underwater_insect_FR_L4_coll_1"         file="underwater_insect_robot/underwater_insect_FR_L4_coll_1.stl" />
        <mesh name="underwater_insect_FR_FOOT_coll_1"       file="underwater_insect_robot/underwater_insect_FR_FOOT_coll_1.stl" />
        <mesh name="underwater_insect_BR_L1_coll_1"         file="underwater_insect_robot/underwater_insect_BR_L1_coll_1.stl" />
        <mesh name="underwater_insect_BR_L2_coll_1"         file="underwater_insect_robot/underwater_insect_BR_L2_coll_1.stl" />
        <mesh name="underwater_insect_BR_L3_coll_1"         file="underwater_insect_robot/underwater_insect_BR_L3_coll_1.stl" />
        <mesh name="underwater_insect_BR_L4_coll_1"         file="underwater_insect_robot/underwater_insect_BR_L4_coll_1.stl" />
        <mesh name="underwater_insect_BR_FOOT_coll_1"       file="underwater_insect_robot/underwater_insect_BR_FOOT_coll_1.stl" />
        <mesh name="underwater_insect_FL_L1_coll_1"         file="underwater_insect_robot/underwater_insect_FL_L1_coll_1.stl" />
        <mesh name="underwater_insect_FL_L2_coll_1"         file="underwater_insect_robot/underwater_insect_FL_L2_coll_1.stl" />
        <mesh name="underwater_insect_FL_L3_coll_1"         file="underwater_insect_robot/underwater_insect_FL_L3_coll_1.stl" />
        <mesh name="underwater_insect_FL_L4_coll_1"         file="underwater_insect_robot/underwater_insect_FL_L4_coll_1.stl" />
        <mesh name="underwater_insect_FL_FOOT_coll_1"       file="underwater_insect_robot/underwater_insect_FL_FOOT_coll_1.stl" />
        <mesh name="underwater_insect_BL_L1_coll_1"         file="underwater_insect_robot/underwater_insect_BL_L1_coll_1.stl" />
        <mesh name="underwater_insect_BL_L2_coll_1"         file="underwater_insect_robot/underwater_insect_BL_L2_coll_1.stl" />
        <mesh name="underwater_insect_BL_L3_coll_1"         file="underwater_insect_robot/underwater_insect_BL_L3_coll_1.stl" />
        <mesh name="underwater_insect_BL_L4_coll_1"         file="underwater_insect_robot/underwater_insect_BL_L4_coll_1.stl" />
        <mesh name="underwater_insect_BL_FOOT_coll_1"       file="underwater_insect_robot/underwater_insect_BL_FOOT_coll_1.stl" />
    </asset>

    
    <worldbody>
        <geom quat="-0.707108 0.707105 0 2.44949e-07" type="mesh" mesh="underwater_insect_robot_base_coll_1" />
        <body name="FR_L1" pos="0.140684 -0.026921 0.339098" quat="0.707103 -0.00241547 -0.00241572 -0.707103">
            <inertial pos="0.000123 0.068716 -0.038767" quat="0.499117 0.500952 -0.502851 0.497062" mass="0.431618" diaginertia="0.000458537 0.000422628 0.00025388" />
            <joint name="FR_J1" pos="0 0 0" axis="0 0 1" />
            <geom quat="-0.707108 0.707105 0 2.44949e-07" type="mesh" mesh="underwater_insect_FR_L1_coll_1" />
            <body name="FR_L2" pos="0 0.113998 -0.039" quat="0.5 0.5 -0.5 0.5">
                <inertial pos="0.000323 0.001645 -0.052271" quat="0.701208 -0.0295292 -0.0254289 0.71189" mass="0.374899" diaginertia="0.000281472 0.000222081 0.00020913" />
                <joint name="FR_J2" pos="0 0 0" axis="0 0 1" />
                <geom quat="-0.707108 0.707105 0 2.44949e-07" type="mesh" mesh="underwater_insect_FR_L2_coll_1" />
                <body name="FR_L3" pos="0 0.039 -0.061002" quat="-0.653281 -0.653281 -0.270598 0.270598">
                    <inertial pos="0.045 0 0.03774" quat="2.44949e-07 0.707107 0 0.707107" mass="0.159476" diaginertia="0.000309795 0.000273197 4.09354e-05" />
                    <joint name="FR_J3" pos="0 0 0" axis="0 0 1" />
                    <geom quat="-0.707108 0.707105 0 2.44949e-07" type="mesh" mesh="underwater_insect_FR_L3_coll_1" />
                    <body name="FR_L4" pos="0.09 0 0.0005" quat="0.923879 9.37378e-08 -2.26303e-07 -0.382684">
                        <inertial pos="0.000717535 -0.0330022 0.037096" quat="0.502157 0.497867 -0.499283 0.500683" mass="0.46319" diaginertia="0.000933369 0.000893362 0.000229344" />
                        <joint name="FR_J4" pos="0 0 0" axis="0 0 1" />
                        <geom quat="-0.707108 0.707105 0 2.44949e-07" type="mesh" mesh="underwater_insect_FR_L4_coll_1" />
                        <geom pos="0 -0.2475 0.0385" quat="-1.53669e-06 0.707107 -1.29174e-06 -0.707107" type="mesh" mesh="underwater_insect_FR_FOOT_coll_1" />
                    </body>
                </body>
            </body>
        </body>
        <body name="BR_L1" pos="0.140684 -0.277715 0.223809" quat="0.707103 -0.00241547 -0.00241572 -0.707103">
            <inertial pos="0.000123 0.068716 -0.038767" quat="0.499117 0.500952 -0.502851 0.497062" mass="0.431618" diaginertia="0.000458537 0.000422628 0.00025388" />
            <joint name="BR_J1" pos="0 0 0" axis="0 0 1" />
            <geom quat="-0.707108 0.707105 0 2.44949e-07" type="mesh" mesh="underwater_insect_BR_L1_coll_1" />
            <body name="BR_L2" pos="0 0.113998 -0.039" quat="0.5 0.5 -0.5 0.5">
                <inertial pos="0.000323 0.001645 -0.052271" quat="0.701208 -0.0295292 -0.0254289 0.71189" mass="0.374899" diaginertia="0.000281472 0.000222081 0.00020913" />
                <joint name="BR_J2" pos="0 0 0" axis="0 0 1" />
                <geom quat="-0.707108 0.707105 0 2.44949e-07" type="mesh" mesh="underwater_insect_BR_L2_coll_1" />
                <body name="BR_L3" pos="0 0.039 -0.061002" quat="-0.653281 -0.653281 -0.270598 0.270598">
                    <inertial pos="0.045 0 0.03774" quat="2.44949e-07 0.707107 0 0.707107" mass="0.159476" diaginertia="0.000309795 0.000273197 4.09354e-05" />
                    <joint name="BR_J3" pos="0 0 0" axis="0 0 1" />
                    <geom quat="-0.707108 0.707105 0 2.44949e-07" type="mesh" mesh="underwater_insect_BR_L3_coll_1" />
                    <body name="BR_L4" pos="0.09 0 0.0005" quat="0.923879 9.37378e-08 -2.26303e-07 -0.382684">
                        <inertial pos="0.000717535 -0.0330022 0.037096" quat="0.502157 0.497867 -0.499283 0.500683" mass="0.46319" diaginertia="0.000933369 0.000893362 0.000229344" />
                        <joint name="BR_J4" pos="0 0 0" axis="0 0 1" />
                        <geom quat="-0.707108 0.707105 0 2.44949e-07" type="mesh" mesh="underwater_insect_BR_L4_coll_1" />
                        <geom pos="0 -0.2475 0.0385" quat="-1.53669e-06 0.707107 -1.29174e-06 -0.707107" type="mesh" mesh="underwater_insect_BR_FOOT_coll_1" />
                    </body>
                </body>
            </body>
        </body>
        <body name="FL_L1" pos="-0.129316 -0.026921 0.339098" quat="0.707103 -0.00241583 0.00241558 0.707103">
            <inertial pos="0.000123 0.068716 -0.038767" quat="0.499117 0.500952 -0.502851 0.497062" mass="0.431618" diaginertia="0.000458537 0.000422628 0.00025388" />
            <joint name="FL_J1" pos="0 0 0" axis="0 0 1" />
            <geom quat="-0.707108 0.707105 0 2.44949e-07" type="mesh" mesh="underwater_insect_FL_L1_coll_1" />
            <body name="FL_L2" pos="0 0.113998 -0.039" quat="0.5 0.5 -0.5 0.5">
                <inertial pos="0.000323 0.001645 -0.052271" quat="0.701208 -0.0295292 -0.0254289 0.71189" mass="0.374899" diaginertia="0.000281472 0.000222081 0.00020913" />
                <joint name="FL_J2" pos="0 0 0" axis="0 0 1" />
                <geom quat="-0.707108 0.707105 0 2.44949e-07" type="mesh" mesh="underwater_insect_FL_L2_coll_1" />
                <body name="FL_L3" pos="0 0.039 -0.061002" quat="-0.653281 -0.653281 -0.270598 0.270598">
                    <inertial pos="0.045 0 0.03774" quat="2.44949e-07 0.707107 0 0.707107" mass="0.159476" diaginertia="0.000309795 0.000273197 4.09354e-05" />
                    <joint name="FL_J3" pos="0 0 0" axis="0 0 1" />
                    <geom quat="-0.707108 0.707105 0 2.44949e-07" type="mesh" mesh="underwater_insect_FL_L3_coll_1" />
                    <body name="FL_L4" pos="0.09 0 0.0005" quat="0.923879 9.37378e-08 -2.26303e-07 -0.382684">
                        <inertial pos="0.000717535 -0.0330022 0.037096" quat="0.502157 0.497867 -0.499283 0.500683" mass="0.46319" diaginertia="0.000933369 0.000893362 0.000229344" />
                        <joint name="FL_J4" pos="0 0 0" axis="0 0 1" />
                        <geom quat="-0.707108 0.707105 0 2.44949e-07" type="mesh" mesh="underwater_insect_FL_L4_coll_1" />
                        <geom pos="0 -0.2475 0.0385" quat="-1.53669e-06 0.707107 -1.29174e-06 -0.707107" type="mesh" mesh="underwater_insect_FL_FOOT_coll_1" />
                    </body>
                </body>
            </body>
        </body>
        <body name="BL_L1" pos="-0.129316 -0.277715 0.223809" quat="0.707103 -0.00241583 0.00241558 0.707103">
            <inertial pos="0.000123 0.068716 -0.038767" quat="0.499117 0.500952 -0.502851 0.497062" mass="0.431618" diaginertia="0.000458537 0.000422628 0.00025388" />
            <joint name="BL_J1" pos="0 0 0" axis="0 0 1" />
            <geom quat="-0.707108 0.707105 0 2.44949e-07" type="mesh" mesh="underwater_insect_BL_L1_coll_1" />
            <body name="BL_L2" pos="0 0.113998 -0.039" quat="0.5 0.5 -0.5 0.5">
                <inertial pos="0.000323 0.001645 -0.052271" quat="0.701208 -0.0295292 -0.0254289 0.71189" mass="0.374899" diaginertia="0.000281472 0.000222081 0.00020913" />
                <joint name="BL_J2" pos="0 0 0" axis="0 0 1" />
                <geom quat="-0.707108 0.707105 0 2.44949e-07" type="mesh" mesh="underwater_insect_BL_L2_coll_1" />
                <body name="BL_L3" pos="0 0.039 -0.061002" quat="-0.653281 -0.653281 -0.270598 0.270598">
                    <inertial pos="0.045 0 0.03774" quat="2.44949e-07 0.707107 0 0.707107" mass="0.159476" diaginertia="0.000309795 0.000273197 4.09354e-05" />
                    <joint name="BL_J3" pos="0 0 0" axis="0 0 1" />
                    <geom quat="-0.707108 0.707105 0 2.44949e-07" type="mesh" mesh="underwater_insect_BL_L3_coll_1" />
                    <body name="BL_L4" pos="0.09 0 0.0005" quat="0.923879 9.37378e-08 -2.26303e-07 -0.382684">
                        <inertial pos="0.000717535 -0.0330022 0.037096" quat="0.502157 0.497867 -0.499283 0.500683" mass="0.46319" diaginertia="0.000933369 0.000893362 0.000229344" />
                        <joint name="BL_J4" pos="0 0 0" axis="0 0 1" />
                        <geom quat="-0.707108 0.707105 0 2.44949e-07" type="mesh" mesh="underwater_insect_BL_L4_coll_1" />
                        <geom pos="0 -0.2475 0.0385" quat="-1.53669e-06 0.707107 -1.29174e-06 -0.707107" type="mesh" mesh="underwater_insect_BL_FOOT_coll_1" />
                    </body>
                </body>
            </body>
        </body>
    </worldbody>
</mujoco>
