<?xml version="1.0"?>
<robot name="Body">
    <link name="robot_base">
        <inertial>
            <origin rpy="-3.141593 3.141593 -3.141593" xyz="-0.069633 0.013890 0.139695" />
            <inertia ixx="0.01" ixy="-6.0584517520974e-28" ixz="9.5925486074875e-28" izz="0.01" iyz="-3.9031278209478e-18" iyy="0.01" />
            <mass value="1.0" />
        </inertial>
        <collision name="Body">
            <origin rpy="1.5708 3.141593 -3.141593" xyz="0.000000 0.000000 0.000000" />
            <geometry>
                <mesh filename="/underwater_insect_robot_base_coll_1.stl" />
            </geometry>
        </collision>
        <visual name="Body">
            <origin rpy="1.5708 3.141593 -3.141593" xyz="0.000000 0.000000 0.000000" />
            <geometry>
                <mesh filename="/underwater_insect_robot_base_vis_1.stl" />
            </geometry>
            <material name="robot_base_material">
                <color rgba="1.000000 1.000000 1.000000 1.0" />
            </material>
        </visual>
    </link>
    <joint type="continuous" name="FR_J1">
        <axis xyz="0 0 1" />
        <parent link="robot_base" />
        <child link="FR_L1" />
        <origin rpy="3.141593 3.148425 1.570796" xyz="0.140684 -0.026921 0.339098" />
    </joint>
    <link name="FR_L1">
        <inertial>
            <origin rpy="-3.141593 3.141593 -3.141593" xyz="0.000123 0.068716 -0.038767" />
            <inertia ixx="0.00042262545229929" ixy="-6.6723429100752e-07" ixz="-7.7696646255367e-12" izz="0.00045852505853081" iyz="-1.5600493380556e-06" iyy="0.00025389438945044" />
            <mass value="0.43161825428487" />
        </inertial>
        <collision name="FR_L1">
            <origin rpy="1.5708 3.141593 -3.141593" xyz="0.000000 0.000000 0.000000" />
            <geometry>
                <mesh filename="/underwater_insect_FR_L1_coll_1.stl" />
            </geometry>
        </collision>
        <visual name="FR_L1">
            <origin rpy="1.5708 3.141593 -3.141593" xyz="0.000000 0.000000 0.000000" />
            <geometry>
                <mesh filename="/underwater_insect_FR_L1_vis_1.stl" />
            </geometry>
            <material name="FR_L1_material">
                <color rgba="1.000000 1.000000 1.000000 1.0" />
            </material>
        </visual>
    </link>
    <joint type="continuous" name="FR_J2">
        <axis xyz="0 0 1" />
        <parent link="FR_L1" />
        <child link="FR_L2" />
        <origin rpy="1.570796 -1.570796 0.000000" xyz="-0.000000 0.113998 -0.039000" />
    </joint>
    <link name="FR_L2">
        <inertial>
            <origin rpy="-3.141593 3.141593 -3.141593" xyz="0.000323 0.001645 -0.052271" />
            <inertia ixx="0.00022201626625888" ixy="-8.7773040888859e-07" ixz="1.0089777432803e-06" izz="0.00020921069757747" iyz="-4.4613585390138e-07" iyy="0.00028145573509855" />
            <mass value="0.37489903469272" />
        </inertial>
        <collision name="FR_L2">
            <origin rpy="1.5708 3.141593 -3.141593" xyz="0.000000 0.000000 0.000000" />
            <geometry>
                <mesh filename="/underwater_insect_FR_L2_coll_1.stl" />
            </geometry>
        </collision>
        <visual name="FR_L2">
            <origin rpy="1.5708 3.141593 -3.141593" xyz="0.000000 0.000000 0.000000" />
            <geometry>
                <mesh filename="/underwater_insect_FR_L2_vis_1.stl" />
            </geometry>
            <material name="FR_L2_material">
                <color rgba="1.000000 1.000000 1.000000 1.0" />
            </material>
        </visual>
    </link>
    <joint type="continuous" name="FR_J3">
        <axis xyz="0 0 1" />
        <parent link="FR_L2" />
        <child link="FR_L3" />
        <origin rpy="-1.570796 2.356194 3.141593" xyz="0.000000 0.039000 -0.061002" />
    </joint>
    <link name="FR_L3">
        <inertial>
            <origin rpy="-3.141593 3.141593 -3.141593" xyz="0.045000 -0.000000 0.037740" />
            <inertia ixx="4.0935444601708e-05" ixy="7.9536159345447e-19" ixz="1.9287518641271e-17" izz="0.00030979476282023" iyz="1.4264637273912e-19" iyy="0.00027319661601516" />
            <mass value="0.15947643217948" />
        </inertial>
        <collision name="FR_L3">
            <origin rpy="1.5708 3.141593 -3.141593" xyz="0.000000 0.000000 0.000000" />
            <geometry>
                <mesh filename="/underwater_insect_FR_L3_coll_1.stl" />
            </geometry>
        </collision>
        <visual name="FR_L3">
            <origin rpy="1.5708 3.141593 -3.141593" xyz="0.000000 0.000000 0.000000" />
            <geometry>
                <mesh filename="/underwater_insect_FR_L3_vis_1.stl" />
            </geometry>
            <material name="FR_L3_material">
                <color rgba="1.000000 1.000000 1.000000 1.0" />
            </material>
        </visual>
    </link>
    <joint type="continuous" name="FR_J4">
        <axis xyz="0 0 1" />
        <parent link="FR_L3" />
        <child link="FR_L4" />
        <origin rpy="3.141593 3.141593 2.356193" xyz="0.090000 0.000000 0.000500" />
    </joint>
    <link name="FR_L4">
        <inertial>
            <origin rpy="-3.141593 3.141593 -3.141593" xyz="0.000738 -0.027228 0.037056" />
            <inertia ixx="0.00035070915333985" ixy="3.5303855587142e-11" ixz="2.7827008346271e-10" izz="0.00039071782362773" iyz="2.5000311136592e-07" iyy="0.00022777533224734" />
            <mass value="0.45034540042746" />
        </inertial>
        <collision name="FR_L4">
            <origin rpy="1.5708 3.141593 -3.141593" xyz="0.000000 0.000000 0.000000" />
            <geometry>
                <mesh filename="/underwater_insect_FR_L4_coll_1.stl" />
            </geometry>
        </collision>
        <visual name="FR_L4">
            <origin rpy="1.5708 3.141593 -3.141593" xyz="0.000000 0.000000 0.000000" />
            <geometry>
                <mesh filename="/underwater_insect_FR_L4_vis_1.stl" />
            </geometry>
            <material name="FR_L4_material">
                <color rgba="1.000000 1.000000 1.000000 1.0" />
            </material>
        </visual>
    </link>
    <joint type="fixed" name="FR_GRF">
        <axis xyz="0 0 1" />
        <parent link="FR_L4" />
        <child link="FR_FOOT" />
        <origin rpy="-1.570796 1.570796 0.000000" xyz="0.000000 -0.247500 0.038500" />
    </joint>
    <link name="FR_FOOT">
        <inertial>
            <origin rpy="-3.141593 3.141593 -3.141593" xyz="0.000000 -0.000000 0.012045" />
            <inertia ixx="1.1474250310693e-06" ixy="-2.3345877110989e-22" ixz="-5.9294378326657e-22" izz="1.5643550022274e-06" iyz="3.8464104274849e-22" iyy="1.1474250310693e-06" />
            <mass value="0.01284448554277" />
        </inertial>
        <collision name="FR_FOOT">
            <origin rpy="1.5708 3.141593 -3.141593" xyz="0.000000 0.000000 0.000000" />
            <geometry>
                <mesh filename="/underwater_insect_FR_FOOT_coll_1.stl" />
            </geometry>
        </collision>
        <visual name="FR_FOOT">
            <origin rpy="1.5708 3.141593 -3.141593" xyz="0.000000 0.000000 0.000000" />
            <geometry>
                <mesh filename="/underwater_insect_FR_FOOT_vis_1.stl" />
            </geometry>
            <material name="FR_FOOT_material">
                <color rgba="1.000000 1.000000 1.000000 1.0" />
            </material>
        </visual>
    </link>
    <joint type="continuous" name="BR_J1">
        <axis xyz="0 0 1" />
        <parent link="robot_base" />
        <child link="BR_L1" />
        <origin rpy="3.141593 3.148425 1.570796" xyz="0.140684 -0.277715 0.223809" />
    </joint>
    <link name="BR_L1">
        <inertial>
            <origin rpy="-3.141593 3.141593 -3.141593" xyz="0.000123 0.068716 -0.038767" />
            <inertia ixx="0.00042262545229929" ixy="-6.672342910075e-07" ixz="-7.7696645239013e-12" izz="0.00045852505853081" iyz="-1.5600493380555e-06" iyy="0.00025389438945044" />
            <mass value="0.43161825428487" />
        </inertial>
        <collision name="BR_L1">
            <origin rpy="1.5708 3.141593 -3.141593" xyz="0.000000 0.000000 0.000000" />
            <geometry>
                <mesh filename="/underwater_insect_BR_L1_coll_1.stl" />
            </geometry>
        </collision>
        <visual name="BR_L1">
            <origin rpy="1.5708 3.141593 -3.141593" xyz="0.000000 0.000000 0.000000" />
            <geometry>
                <mesh filename="/underwater_insect_BR_L1_vis_1.stl" />
            </geometry>
            <material name="BR_L1_material">
                <color rgba="1.000000 1.000000 1.000000 1.0" />
            </material>
        </visual>
    </link>
    <joint type="continuous" name="BR_J2">
        <axis xyz="0 0 1" />
        <parent link="BR_L1" />
        <child link="BR_L2" />
        <origin rpy="1.570796 -1.570796 0.000000" xyz="-0.000000 0.113998 -0.039000" />
    </joint>
    <link name="BR_L2">
        <inertial>
            <origin rpy="-3.141593 3.141593 -3.141593" xyz="0.000323 0.001645 -0.052271" />
            <inertia ixx="0.00022201626625888" ixy="-8.777304088886e-07" ixz="1.0089777432803e-06" izz="0.00020921069757747" iyz="-4.4613585390138e-07" iyy="0.00028145573509855" />
            <mass value="0.37489903469272" />
        </inertial>
        <collision name="BR_L2">
            <origin rpy="1.5708 3.141593 -3.141593" xyz="0.000000 0.000000 0.000000" />
            <geometry>
                <mesh filename="/underwater_insect_BR_L2_coll_1.stl" />
            </geometry>
        </collision>
        <visual name="BR_L2">
            <origin rpy="1.5708 3.141593 -3.141593" xyz="0.000000 0.000000 0.000000" />
            <geometry>
                <mesh filename="/underwater_insect_BR_L2_vis_1.stl" />
            </geometry>
            <material name="BR_L2_material">
                <color rgba="1.000000 1.000000 1.000000 1.0" />
            </material>
        </visual>
    </link>
    <joint type="continuous" name="BR_J3">
        <axis xyz="0 0 1" />
        <parent link="BR_L2" />
        <child link="BR_L3" />
        <origin rpy="-1.570796 2.356194 3.141593" xyz="0.000000 0.039000 -0.061002" />
    </joint>
    <link name="BR_L3">
        <inertial>
            <origin rpy="-3.141593 3.141593 -3.141593" xyz="0.045000 -0.000000 0.037740" />
            <inertia ixx="4.0935444601708e-05" ixy="6.0516642980231e-19" ixz="1.9428273868917e-17" izz="0.00030979476282023" iyz="7.4294985801623e-20" iyy="0.00027319661601516" />
            <mass value="0.15947643217948" />
        </inertial>
        <collision name="BR_L3">
            <origin rpy="1.5708 3.141593 -3.141593" xyz="0.000000 0.000000 0.000000" />
            <geometry>
                <mesh filename="/underwater_insect_BR_L3_coll_1.stl" />
            </geometry>
        </collision>
        <visual name="BR_L3">
            <origin rpy="1.5708 3.141593 -3.141593" xyz="0.000000 0.000000 0.000000" />
            <geometry>
                <mesh filename="/underwater_insect_BR_L3_vis_1.stl" />
            </geometry>
            <material name="BR_L3_material">
                <color rgba="1.000000 1.000000 1.000000 1.0" />
            </material>
        </visual>
    </link>
    <joint type="continuous" name="BR_J4">
        <axis xyz="0 0 1" />
        <parent link="BR_L3" />
        <child link="BR_L4" />
        <origin rpy="3.141593 3.141593 2.356193" xyz="0.090000 0.000000 0.000500" />
    </joint>
    <link name="BR_L4">
        <inertial>
            <origin rpy="-3.141593 3.141593 -3.141593" xyz="0.000738 -0.027228 0.037056" />
            <inertia ixx="0.00035070915333985" ixy="3.5303855686344e-11" ixz="2.7827008350512e-10" izz="0.00039071782362773" iyz="2.5000311136596e-07" iyy="0.00022777533224734" />
            <mass value="0.45034540042746" />
        </inertial>
        <collision name="BR_L4">
            <origin rpy="1.5708 3.141593 -3.141593" xyz="0.000000 0.000000 0.000000" />
            <geometry>
                <mesh filename="/underwater_insect_BR_L4_coll_1.stl" />
            </geometry>
        </collision>
        <visual name="BR_L4">
            <origin rpy="1.5708 3.141593 -3.141593" xyz="0.000000 0.000000 0.000000" />
            <geometry>
                <mesh filename="/underwater_insect_BR_L4_vis_1.stl" />
            </geometry>
            <material name="BR_L4_material">
                <color rgba="1.000000 1.000000 1.000000 1.0" />
            </material>
        </visual>
    </link>
    <joint type="fixed" name="BR_GRF">
        <axis xyz="0 0 1" />
        <parent link="BR_L4" />
        <child link="BR_FOOT" />
        <origin rpy="-1.570796 1.570796 0.000000" xyz="0.000000 -0.247500 0.038500" />
    </joint>
    <link name="BR_FOOT">
        <inertial>
            <origin rpy="-3.141593 3.141593 -3.141593" xyz="-0.000000 -0.000000 0.012045" />
            <inertia ixx="1.1474250310693e-06" ixy="-3.3367405746013e-23" ixz="-3.2639107335774e-23" izz="1.5643550022274e-06" iyz="3.9145413766355e-22" iyy="1.1474250310693e-06" />
            <mass value="0.01284448554277" />
        </inertial>
        <collision name="BR_FOOT">
            <origin rpy="1.5708 3.141593 -3.141593" xyz="0.000000 0.000000 0.000000" />
            <geometry>
                <mesh filename="/underwater_insect_BR_FOOT_coll_1.stl" />
            </geometry>
        </collision>
        <visual name="BR_FOOT">
            <origin rpy="1.5708 3.141593 -3.141593" xyz="0.000000 0.000000 0.000000" />
            <geometry>
                <mesh filename="/underwater_insect_BR_FOOT_vis_1.stl" />
            </geometry>
            <material name="BR_FOOT_material">
                <color rgba="1.000000 1.000000 1.000000 1.0" />
            </material>
        </visual>
    </link>
    <joint type="continuous" name="FL_J1">
        <axis xyz="0 0 1" />
        <parent link="robot_base" />
        <child link="FL_L1" />
        <origin rpy="-3.141593 3.134760 -1.570796" xyz="-0.129316 -0.026921 0.339098" />
    </joint>
    <link name="FL_L1">
        <inertial>
            <origin rpy="-3.141593 3.141593 -3.141593" xyz="0.000123 0.068716 -0.038767" />
            <inertia ixx="0.00042262545229929" ixy="-6.6723429100764e-07" ixz="-7.7696645184174e-12" izz="0.0004585250585308" iyz="-1.5600493380555e-06" iyy="0.00025389438945044" />
            <mass value="0.43161825428487" />
        </inertial>
        <collision name="FL_L1">
            <origin rpy="1.5708 3.141593 -3.141593" xyz="0.000000 0.000000 0.000000" />
            <geometry>
                <mesh filename="/underwater_insect_FL_L1_coll_1.stl" />
            </geometry>
        </collision>
        <visual name="FL_L1">
            <origin rpy="1.5708 3.141593 -3.141593" xyz="0.000000 0.000000 0.000000" />
            <geometry>
                <mesh filename="/underwater_insect_FL_L1_vis_1.stl" />
            </geometry>
            <material name="FL_L1_material">
                <color rgba="1.000000 1.000000 1.000000 1.0" />
            </material>
        </visual>
    </link>
    <joint type="continuous" name="FL_J2">
        <axis xyz="0 0 1" />
        <parent link="FL_L1" />
        <child link="FL_L2" />
        <origin rpy="1.570796 -1.570796 0.000000" xyz="0.000000 0.113998 -0.039000" />
    </joint>
    <link name="FL_L2">
        <inertial>
            <origin rpy="-3.141593 3.141593 -3.141593" xyz="0.000323 0.001645 -0.052271" />
            <inertia ixx="0.00022201626625888" ixy="-8.777304088886e-07" ixz="1.0089777432801e-06" izz="0.00020921069757747" iyz="-4.4613585390138e-07" iyy="0.00028145573509855" />
            <mass value="0.37489903469272" />
        </inertial>
        <collision name="FL_L2">
            <origin rpy="1.5708 3.141593 -3.141593" xyz="0.000000 0.000000 0.000000" />
            <geometry>
                <mesh filename="/underwater_insect_FL_L2_coll_1.stl" />
            </geometry>
        </collision>
        <visual name="FL_L2">
            <origin rpy="1.5708 3.141593 -3.141593" xyz="0.000000 0.000000 0.000000" />
            <geometry>
                <mesh filename="/underwater_insect_FL_L2_vis_1.stl" />
            </geometry>
            <material name="FL_L2_material">
                <color rgba="1.000000 1.000000 1.000000 1.0" />
            </material>
        </visual>
    </link>
    <joint type="continuous" name="FL_J3">
        <axis xyz="0 0 1" />
        <parent link="FL_L2" />
        <child link="FL_L3" />
        <origin rpy="-1.570796 2.356194 3.141593" xyz="0.000000 0.039000 -0.061002" />
    </joint>
    <link name="FL_L3">
        <inertial>
            <origin rpy="-3.141593 3.141593 -3.141593" xyz="0.045000 -0.000000 0.037740" />
            <inertia ixx="4.0935444601709e-05" ixy="4.49552204996e-19" ixz="1.9345603811988e-17" izz="0.00030979476282023" iyz="-2.4638918927665e-19" iyy="0.00027319661601516" />
            <mass value="0.15947643217948" />
        </inertial>
        <collision name="FL_L3">
            <origin rpy="1.5708 3.141593 -3.141593" xyz="0.000000 0.000000 0.000000" />
            <geometry>
                <mesh filename="/underwater_insect_FL_L3_coll_1.stl" />
            </geometry>
        </collision>
        <visual name="FL_L3">
            <origin rpy="1.5708 3.141593 -3.141593" xyz="0.000000 0.000000 0.000000" />
            <geometry>
                <mesh filename="/underwater_insect_FL_L3_vis_1.stl" />
            </geometry>
            <material name="FL_L3_material">
                <color rgba="1.000000 1.000000 1.000000 1.0" />
            </material>
        </visual>
    </link>
    <joint type="continuous" name="FL_J4">
        <axis xyz="0 0 1" />
        <parent link="FL_L3" />
        <child link="FL_L4" />
        <origin rpy="3.141593 3.141593 2.356193" xyz="0.090000 0.000000 0.000500" />
    </joint>
    <link name="FL_L4">
        <inertial>
            <origin rpy="-3.141593 3.141593 -3.141593" xyz="0.000738 -0.027228 0.037056" />
            <inertia ixx="0.00035070915333985" ixy="3.5303855686344e-11" ixz="2.7827008350512e-10" izz="0.00039071782362773" iyz="2.500031113657e-07" iyy="0.00022777533224734" />
            <mass value="0.45034540042746" />
        </inertial>
        <collision name="FL_L4">
            <origin rpy="1.5708 3.141593 -3.141593" xyz="0.000000 0.000000 0.000000" />
            <geometry>
                <mesh filename="/underwater_insect_FL_L4_coll_1.stl" />
            </geometry>
        </collision>
        <visual name="FL_L4">
            <origin rpy="1.5708 3.141593 -3.141593" xyz="0.000000 0.000000 0.000000" />
            <geometry>
                <mesh filename="/underwater_insect_FL_L4_vis_1.stl" />
            </geometry>
            <material name="FL_L4_material">
                <color rgba="1.000000 1.000000 1.000000 1.0" />
            </material>
        </visual>
    </link>
    <joint type="fixed" name="FL_GRF">
        <axis xyz="0 0 1" />
        <parent link="FL_L4" />
        <child link="FL_FOOT" />
        <origin rpy="-1.570796 1.570796 0.000000" xyz="0.000000 -0.247500 0.038500" />
    </joint>
    <link name="FL_FOOT">
        <inertial>
            <origin rpy="-3.141593 3.141593 -3.141593" xyz="0.000000 0.000000 0.012045" />
            <inertia ixx="1.1474250310693e-06" ixy="-5.1911798467943e-23" ixz="-3.2639107335774e-23" izz="1.5643550022274e-06" iyz="3.8838758090744e-22" iyy="1.1474250310693e-06" />
            <mass value="0.01284448554277" />
        </inertial>
        <collision name="FL_FOOT">
            <origin rpy="1.5708 3.141593 -3.141593" xyz="0.000000 0.000000 0.000000" />
            <geometry>
                <mesh filename="/underwater_insect_FL_FOOT_coll_1.stl" />
            </geometry>
        </collision>
        <visual name="FL_FOOT">
            <origin rpy="1.5708 3.141593 -3.141593" xyz="0.000000 0.000000 0.000000" />
            <geometry>
                <mesh filename="/underwater_insect_FL_FOOT_vis_1.stl" />
            </geometry>
            <material name="FL_FOOT_material">
                <color rgba="1.000000 1.000000 1.000000 1.0" />
            </material>
        </visual>
    </link>
    <joint type="continuous" name="BL_J1">
        <axis xyz="0 0 1" />
        <parent link="robot_base" />
        <child link="BL_L1" />
        <origin rpy="-3.141593 3.134760 -1.570796" xyz="-0.129316 -0.277715 0.223809" />
    </joint>
    <link name="BL_L1">
        <inertial>
            <origin rpy="-3.141593 3.141593 -3.141593" xyz="0.000123 0.068716 -0.038767" />
            <inertia ixx="0.00042262545229929" ixy="-6.6723429100764e-07" ixz="-7.7696645184174e-12" izz="0.0004585250585308" iyz="-1.5600493380555e-06" iyy="0.00025389438945044" />
            <mass value="0.43161825428487" />
        </inertial>
        <collision name="BL_L1">
            <origin rpy="1.5708 3.141593 -3.141593" xyz="0.000000 0.000000 0.000000" />
            <geometry>
                <mesh filename="/underwater_insect_BL_L1_coll_1.stl" />
            </geometry>
        </collision>
        <visual name="BL_L1">
            <origin rpy="1.5708 3.141593 -3.141593" xyz="0.000000 0.000000 0.000000" />
            <geometry>
                <mesh filename="/underwater_insect_BL_L1_vis_1.stl" />
            </geometry>
            <material name="BL_L1_material">
                <color rgba="1.000000 1.000000 1.000000 1.0" />
            </material>
        </visual>
    </link>
    <joint type="continuous" name="BL_J2">
        <axis xyz="0 0 1" />
        <parent link="BL_L1" />
        <child link="BL_L2" />
        <origin rpy="1.570796 -1.570796 0.000000" xyz="0.000000 0.113998 -0.039000" />
    </joint>
    <link name="BL_L2">
        <inertial>
            <origin rpy="-3.141593 3.141593 -3.141593" xyz="0.000323 0.001645 -0.052271" />
            <inertia ixx="0.00022201626625888" ixy="-8.777304088886e-07" ixz="1.0089777432801e-06" izz="0.00020921069757747" iyz="-4.4613585390138e-07" iyy="0.00028145573509855" />
            <mass value="0.37489903469272" />
        </inertial>
        <collision name="BL_L2">
            <origin rpy="1.5708 3.141593 -3.141593" xyz="0.000000 0.000000 0.000000" />
            <geometry>
                <mesh filename="/underwater_insect_BL_L2_coll_1.stl" />
            </geometry>
        </collision>
        <visual name="BL_L2">
            <origin rpy="1.5708 3.141593 -3.141593" xyz="0.000000 0.000000 0.000000" />
            <geometry>
                <mesh filename="/underwater_insect_BL_L2_vis_1.stl" />
            </geometry>
            <material name="BL_L2_material">
                <color rgba="1.000000 1.000000 1.000000 1.0" />
            </material>
        </visual>
    </link>
    <joint type="continuous" name="BL_J3">
        <axis xyz="0 0 1" />
        <parent link="BL_L2" />
        <child link="BL_L3" />
        <origin rpy="-1.570796 2.356194 3.141593" xyz="0.000000 0.039000 -0.061002" />
    </joint>
    <link name="BL_L3">
        <inertial>
            <origin rpy="-3.141593 3.141593 -3.141593" xyz="0.045000 -0.000000 0.037740" />
            <inertia ixx="4.0935444601709e-05" ixy="4.49552204996e-19" ixz="1.9345603811988e-17" izz="0.00030979476282023" iyz="-2.4638918927665e-19" iyy="0.00027319661601516" />
            <mass value="0.15947643217948" />
        </inertial>
        <collision name="BL_L3">
            <origin rpy="1.5708 3.141593 -3.141593" xyz="0.000000 0.000000 0.000000" />
            <geometry>
                <mesh filename="/underwater_insect_BL_L3_coll_1.stl" />
            </geometry>
        </collision>
        <visual name="BL_L3">
            <origin rpy="1.5708 3.141593 -3.141593" xyz="0.000000 0.000000 0.000000" />
            <geometry>
                <mesh filename="/underwater_insect_BL_L3_vis_1.stl" />
            </geometry>
            <material name="BL_L3_material">
                <color rgba="1.000000 1.000000 1.000000 1.0" />
            </material>
        </visual>
    </link>
    <joint type="continuous" name="BL_J4">
        <axis xyz="0 0 1" />
        <parent link="BL_L3" />
        <child link="BL_L4" />
        <origin rpy="3.141593 3.141593 2.356193" xyz="0.090000 0.000000 0.000500" />
    </joint>
    <link name="BL_L4">
        <inertial>
            <origin rpy="-3.141593 3.141593 -3.141593" xyz="0.000738 -0.027228 0.037056" />
            <inertia ixx="0.00035070915333985" ixy="3.5303855686344e-11" ixz="2.7827008350512e-10" izz="0.00039071782362773" iyz="2.500031113657e-07" iyy="0.00022777533224734" />
            <mass value="0.45034540042746" />
        </inertial>
        <collision name="BL_L4">
            <origin rpy="1.5708 3.141593 -3.141593" xyz="0.000000 0.000000 0.000000" />
            <geometry>
                <mesh filename="/underwater_insect_BL_L4_coll_1.stl" />
            </geometry>
        </collision>
        <visual name="BL_L4">
            <origin rpy="1.5708 3.141593 -3.141593" xyz="0.000000 0.000000 0.000000" />
            <geometry>
                <mesh filename="/underwater_insect_BL_L4_vis_1.stl" />
            </geometry>
            <material name="BL_L4_material">
                <color rgba="1.000000 1.000000 1.000000 1.0" />
            </material>
        </visual>
    </link>
    <joint type="fixed" name="BL_GRF">
        <axis xyz="0 0 1" />
        <parent link="BL_L4" />
        <child link="BL_FOOT" />
        <origin rpy="-1.570796 1.570796 0.000000" xyz="-0.000000 -0.247500 0.038500" />
    </joint>
    <link name="BL_FOOT">
        <inertial>
            <origin rpy="-3.141593 3.141593 -3.141593" xyz="-0.000000 0.000000 0.012045" />
            <inertia ixx="1.1474250310693e-06" ixy="-5.1911798467943e-23" ixz="-3.2639107335774e-23" izz="1.5643550022274e-06" iyz="3.8838758090744e-22" iyy="1.1474250310693e-06" />
            <mass value="0.01284448554277" />
        </inertial>
        <collision name="BL_FOOT">
            <origin rpy="1.5708 3.141593 -3.141593" xyz="0.000000 0.000000 0.000000" />
            <geometry>
                <mesh filename="/underwater_insect_BL_FOOT_coll_1.stl" />
            </geometry>
        </collision>
        <visual name="BL_FOOT">
            <origin rpy="1.5708 3.141593 -3.141593" xyz="0.000000 0.000000 0.000000" />
            <geometry>
                <mesh filename="/underwater_insect_BL_FOOT_vis_1.stl" />
            </geometry>
            <material name="BL_FOOT_material">
                <color rgba="1.000000 1.000000 1.000000 1.0" />
            </material>
        </visual>
    </link>
</robot>
